2025-07-12 13:35:56,024 - ERROR - Error sending data to Supabase table 'online_status': [Errno 60] Operation timed out
Traceback (most recent call last):
  File "/Users/adeoluwa/Documents/WorkTrackerApp/work_tracker_venv/lib/python3.13/site-packages/httpx/_transports/default.py", line 101, in map_httpcore_exceptions
    yield
  File "/Users/adeoluwa/Documents/WorkTrackerApp/work_tracker_venv/lib/python3.13/site-packages/httpx/_transports/default.py", line 250, in handle_request
    resp = self._pool.handle_request(req)
  File "/Users/adeoluwa/Documents/WorkTrackerApp/work_tracker_venv/lib/python3.13/site-packages/httpcore/_sync/connection_pool.py", line 256, in handle_request
    raise exc from None
  File "/Users/adeoluwa/Documents/WorkTrackerApp/work_tracker_venv/lib/python3.13/site-packages/httpcore/_sync/connection_pool.py", line 236, in handle_request
    response = connection.handle_request(
        pool_request.request
    )
  File "/Users/adeoluwa/Documents/WorkTrackerApp/work_tracker_venv/lib/python3.13/site-packages/httpcore/_sync/connection.py", line 101, in handle_request
    raise exc
  File "/Users/adeoluwa/Documents/WorkTrackerApp/work_tracker_venv/lib/python3.13/site-packages/httpcore/_sync/connection.py", line 78, in handle_request
    stream = self._connect(request)
  File "/Users/adeoluwa/Documents/WorkTrackerApp/work_tracker_venv/lib/python3.13/site-packages/httpcore/_sync/connection.py", line 124, in _connect
    stream = self._network_backend.connect_tcp(**kwargs)
  File "/Users/adeoluwa/Documents/WorkTrackerApp/work_tracker_venv/lib/python3.13/site-packages/httpcore/_backends/sync.py", line 207, in connect_tcp
    with map_exceptions(exc_map):
         ~~~~~~~~~~~~~~^^^^^^^^^
  File "/Library/Frameworks/Python.framework/Versions/3.13/lib/python3.13/contextlib.py", line 162, in __exit__
    self.gen.throw(value)
    ~~~~~~~~~~~~~~^^^^^^^
  File "/Users/adeoluwa/Documents/WorkTrackerApp/work_tracker_venv/lib/python3.13/site-packages/httpcore/_exceptions.py", line 14, in map_exceptions
    raise to_exc(exc) from exc
httpcore.ConnectTimeout: [Errno 60] Operation timed out

The above exception was the direct cause of the following exception:

Traceback (most recent call last):
  File "/Users/adeoluwa/Documents/WorkTrackerApp/main.py", line 301, in _send_supabase_data
    response = self.supabase_client.table(table_name).upsert(data).execute()
  File "/Users/adeoluwa/Documents/WorkTrackerApp/work_tracker_venv/lib/python3.13/site-packages/postgrest/_sync/request_builder.py", line 57, in execute
    r = self.session.request(
        self.http_method,
    ...<3 lines>...
        headers=self.headers,
    )
  File "/Users/adeoluwa/Documents/WorkTrackerApp/work_tracker_venv/lib/python3.13/site-packages/httpx/_client.py", line 825, in request
    return self.send(request, auth=auth, follow_redirects=follow_redirects)
           ~~~~~~~~~^^^^^^^^^^^^^^^^^^^^^^^^^^^^^^^^^^^^^^^^^^^^^^^^^^^^^^^
  File "/Users/adeoluwa/Documents/WorkTrackerApp/work_tracker_venv/lib/python3.13/site-packages/httpx/_client.py", line 914, in send
    response = self._send_handling_auth(
        request,
    ...<2 lines>...
        history=[],
    )
  File "/Users/adeoluwa/Documents/WorkTrackerApp/work_tracker_venv/lib/python3.13/site-packages/httpx/_client.py", line 942, in _send_handling_auth
    response = self._send_handling_redirects(
        request,
        follow_redirects=follow_redirects,
        history=history,
    )
  File "/Users/adeoluwa/Documents/WorkTrackerApp/work_tracker_venv/lib/python3.13/site-packages/httpx/_client.py", line 979, in _send_handling_redirects
    response = self._send_single_request(request)
  File "/Users/adeoluwa/Documents/WorkTrackerApp/work_tracker_venv/lib/python3.13/site-packages/httpx/_client.py", line 1014, in _send_single_request
    response = transport.handle_request(request)
  File "/Users/adeoluwa/Documents/WorkTrackerApp/work_tracker_venv/lib/python3.13/site-packages/httpx/_transports/default.py", line 249, in handle_request
    with map_httpcore_exceptions():
         ~~~~~~~~~~~~~~~~~~~~~~~^^
  File "/Library/Frameworks/Python.framework/Versions/3.13/lib/python3.13/contextlib.py", line 162, in __exit__
    self.gen.throw(value)
    ~~~~~~~~~~~~~~^^^^^^^
  File "/Users/adeoluwa/Documents/WorkTrackerApp/work_tracker_venv/lib/python3.13/site-packages/httpx/_transports/default.py", line 118, in map_httpcore_exceptions
    raise mapped_exc(message) from exc
httpx.ConnectTimeout: [Errno 60] Operation timed out
2025-07-12 13:35:56,034 - ERROR - Failed to send heartbeat to cloud.
2025-07-12 14:03:10,604 - ERROR - Error sending data to Supabase table 'online_status': [Errno 60] Operation timed out
Traceback (most recent call last):
  File "/Users/adeoluwa/Documents/WorkTrackerApp/work_tracker_venv/lib/python3.13/site-packages/httpx/_transports/default.py", line 101, in map_httpcore_exceptions
    yield
  File "/Users/adeoluwa/Documents/WorkTrackerApp/work_tracker_venv/lib/python3.13/site-packages/httpx/_transports/default.py", line 250, in handle_request
    resp = self._pool.handle_request(req)
  File "/Users/adeoluwa/Documents/WorkTrackerApp/work_tracker_venv/lib/python3.13/site-packages/httpcore/_sync/connection_pool.py", line 256, in handle_request
    raise exc from None
  File "/Users/adeoluwa/Documents/WorkTrackerApp/work_tracker_venv/lib/python3.13/site-packages/httpcore/_sync/connection_pool.py", line 236, in handle_request
    response = connection.handle_request(
        pool_request.request
    )
  File "/Users/adeoluwa/Documents/WorkTrackerApp/work_tracker_venv/lib/python3.13/site-packages/httpcore/_sync/connection.py", line 101, in handle_request
    raise exc
  File "/Users/adeoluwa/Documents/WorkTrackerApp/work_tracker_venv/lib/python3.13/site-packages/httpcore/_sync/connection.py", line 78, in handle_request
    stream = self._connect(request)
  File "/Users/adeoluwa/Documents/WorkTrackerApp/work_tracker_venv/lib/python3.13/site-packages/httpcore/_sync/connection.py", line 124, in _connect
    stream = self._network_backend.connect_tcp(**kwargs)
  File "/Users/adeoluwa/Documents/WorkTrackerApp/work_tracker_venv/lib/python3.13/site-packages/httpcore/_backends/sync.py", line 207, in connect_tcp
    with map_exceptions(exc_map):
         ~~~~~~~~~~~~~~^^^^^^^^^
  File "/Library/Frameworks/Python.framework/Versions/3.13/lib/python3.13/contextlib.py", line 162, in __exit__
    self.gen.throw(value)
    ~~~~~~~~~~~~~~^^^^^^^
  File "/Users/adeoluwa/Documents/WorkTrackerApp/work_tracker_venv/lib/python3.13/site-packages/httpcore/_exceptions.py", line 14, in map_exceptions
    raise to_exc(exc) from exc
httpcore.ConnectTimeout: [Errno 60] Operation timed out

The above exception was the direct cause of the following exception:

Traceback (most recent call last):
  File "/Users/adeoluwa/Documents/WorkTrackerApp/main.py", line 301, in _send_supabase_data
    response = self.supabase_client.table(table_name).upsert(data).execute()
  File "/Users/adeoluwa/Documents/WorkTrackerApp/work_tracker_venv/lib/python3.13/site-packages/postgrest/_sync/request_builder.py", line 57, in execute
    r = self.session.request(
        self.http_method,
    ...<3 lines>...
        headers=self.headers,
    )
  File "/Users/adeoluwa/Documents/WorkTrackerApp/work_tracker_venv/lib/python3.13/site-packages/httpx/_client.py", line 825, in request
    return self.send(request, auth=auth, follow_redirects=follow_redirects)
           ~~~~~~~~~^^^^^^^^^^^^^^^^^^^^^^^^^^^^^^^^^^^^^^^^^^^^^^^^^^^^^^^
  File "/Users/adeoluwa/Documents/WorkTrackerApp/work_tracker_venv/lib/python3.13/site-packages/httpx/_client.py", line 914, in send
    response = self._send_handling_auth(
        request,
    ...<2 lines>...
        history=[],
    )
  File "/Users/adeoluwa/Documents/WorkTrackerApp/work_tracker_venv/lib/python3.13/site-packages/httpx/_client.py", line 942, in _send_handling_auth
    response = self._send_handling_redirects(
        request,
        follow_redirects=follow_redirects,
        history=history,
    )
  File "/Users/adeoluwa/Documents/WorkTrackerApp/work_tracker_venv/lib/python3.13/site-packages/httpx/_client.py", line 979, in _send_handling_redirects
    response = self._send_single_request(request)
  File "/Users/adeoluwa/Documents/WorkTrackerApp/work_tracker_venv/lib/python3.13/site-packages/httpx/_client.py", line 1014, in _send_single_request
    response = transport.handle_request(request)
  File "/Users/adeoluwa/Documents/WorkTrackerApp/work_tracker_venv/lib/python3.13/site-packages/httpx/_transports/default.py", line 249, in handle_request
    with map_httpcore_exceptions():
         ~~~~~~~~~~~~~~~~~~~~~~~^^
  File "/Library/Frameworks/Python.framework/Versions/3.13/lib/python3.13/contextlib.py", line 162, in __exit__
    self.gen.throw(value)
    ~~~~~~~~~~~~~~^^^^^^^
  File "/Users/adeoluwa/Documents/WorkTrackerApp/work_tracker_venv/lib/python3.13/site-packages/httpx/_transports/default.py", line 118, in map_httpcore_exceptions
    raise mapped_exc(message) from exc
httpx.ConnectTimeout: [Errno 60] Operation timed out
2025-07-12 14:03:10,613 - ERROR - Failed to send heartbeat to cloud.
2025-07-12 14:51:23,649 - ERROR - Error sending data to Supabase table 'online_status': [Errno 8] nodename nor servname provided, or not known
Traceback (most recent call last):
  File "/Users/adeoluwa/Documents/WorkTrackerApp/work_tracker_venv/lib/python3.13/site-packages/httpx/_transports/default.py", line 101, in map_httpcore_exceptions
    yield
  File "/Users/adeoluwa/Documents/WorkTrackerApp/work_tracker_venv/lib/python3.13/site-packages/httpx/_transports/default.py", line 250, in handle_request
    resp = self._pool.handle_request(req)
  File "/Users/adeoluwa/Documents/WorkTrackerApp/work_tracker_venv/lib/python3.13/site-packages/httpcore/_sync/connection_pool.py", line 256, in handle_request
    raise exc from None
  File "/Users/adeoluwa/Documents/WorkTrackerApp/work_tracker_venv/lib/python3.13/site-packages/httpcore/_sync/connection_pool.py", line 236, in handle_request
    response = connection.handle_request(
        pool_request.request
    )
  File "/Users/adeoluwa/Documents/WorkTrackerApp/work_tracker_venv/lib/python3.13/site-packages/httpcore/_sync/connection.py", line 101, in handle_request
    raise exc
  File "/Users/adeoluwa/Documents/WorkTrackerApp/work_tracker_venv/lib/python3.13/site-packages/httpcore/_sync/connection.py", line 78, in handle_request
    stream = self._connect(request)
  File "/Users/adeoluwa/Documents/WorkTrackerApp/work_tracker_venv/lib/python3.13/site-packages/httpcore/_sync/connection.py", line 124, in _connect
    stream = self._network_backend.connect_tcp(**kwargs)
  File "/Users/adeoluwa/Documents/WorkTrackerApp/work_tracker_venv/lib/python3.13/site-packages/httpcore/_backends/sync.py", line 207, in connect_tcp
    with map_exceptions(exc_map):
         ~~~~~~~~~~~~~~^^^^^^^^^
  File "/Library/Frameworks/Python.framework/Versions/3.13/lib/python3.13/contextlib.py", line 162, in __exit__
    self.gen.throw(value)
    ~~~~~~~~~~~~~~^^^^^^^
  File "/Users/adeoluwa/Documents/WorkTrackerApp/work_tracker_venv/lib/python3.13/site-packages/httpcore/_exceptions.py", line 14, in map_exceptions
    raise to_exc(exc) from exc
httpcore.ConnectError: [Errno 8] nodename nor servname provided, or not known

The above exception was the direct cause of the following exception:

Traceback (most recent call last):
  File "/Users/adeoluwa/Documents/WorkTrackerApp/main.py", line 301, in _send_supabase_data
    response = self.supabase_client.table(table_name).upsert(data).execute()
  File "/Users/adeoluwa/Documents/WorkTrackerApp/work_tracker_venv/lib/python3.13/site-packages/postgrest/_sync/request_builder.py", line 57, in execute
    r = self.session.request(
        self.http_method,
    ...<3 lines>...
        headers=self.headers,
    )
  File "/Users/adeoluwa/Documents/WorkTrackerApp/work_tracker_venv/lib/python3.13/site-packages/httpx/_client.py", line 825, in request
    return self.send(request, auth=auth, follow_redirects=follow_redirects)
           ~~~~~~~~~^^^^^^^^^^^^^^^^^^^^^^^^^^^^^^^^^^^^^^^^^^^^^^^^^^^^^^^
  File "/Users/adeoluwa/Documents/WorkTrackerApp/work_tracker_venv/lib/python3.13/site-packages/httpx/_client.py", line 914, in send
    response = self._send_handling_auth(
        request,
    ...<2 lines>...
        history=[],
    )
  File "/Users/adeoluwa/Documents/WorkTrackerApp/work_tracker_venv/lib/python3.13/site-packages/httpx/_client.py", line 942, in _send_handling_auth
    response = self._send_handling_redirects(
        request,
        follow_redirects=follow_redirects,
        history=history,
    )
  File "/Users/adeoluwa/Documents/WorkTrackerApp/work_tracker_venv/lib/python3.13/site-packages/httpx/_client.py", line 979, in _send_handling_redirects
    response = self._send_single_request(request)
  File "/Users/adeoluwa/Documents/WorkTrackerApp/work_tracker_venv/lib/python3.13/site-packages/httpx/_client.py", line 1014, in _send_single_request
    response = transport.handle_request(request)
  File "/Users/adeoluwa/Documents/WorkTrackerApp/work_tracker_venv/lib/python3.13/site-packages/httpx/_transports/default.py", line 249, in handle_request
    with map_httpcore_exceptions():
         ~~~~~~~~~~~~~~~~~~~~~~~^^
  File "/Library/Frameworks/Python.framework/Versions/3.13/lib/python3.13/contextlib.py", line 162, in __exit__
    self.gen.throw(value)
    ~~~~~~~~~~~~~~^^^^^^^
  File "/Users/adeoluwa/Documents/WorkTrackerApp/work_tracker_venv/lib/python3.13/site-packages/httpx/_transports/default.py", line 118, in map_httpcore_exceptions
    raise mapped_exc(message) from exc
httpx.ConnectError: [Errno 8] nodename nor servname provided, or not known
2025-07-12 14:51:23,657 - ERROR - Failed to send heartbeat to cloud.
2025-07-12 16:39:19,993 - ERROR - Error sending data to Supabase table 'online_status': [Errno 54] Connection reset by peer
Traceback (most recent call last):
  File "/Users/adeoluwa/Documents/WorkTrackerApp/work_tracker_venv/lib/python3.13/site-packages/httpx/_transports/default.py", line 101, in map_httpcore_exceptions
    yield
  File "/Users/adeoluwa/Documents/WorkTrackerApp/work_tracker_venv/lib/python3.13/site-packages/httpx/_transports/default.py", line 250, in handle_request
    resp = self._pool.handle_request(req)
  File "/Users/adeoluwa/Documents/WorkTrackerApp/work_tracker_venv/lib/python3.13/site-packages/httpcore/_sync/connection_pool.py", line 256, in handle_request
    raise exc from None
  File "/Users/adeoluwa/Documents/WorkTrackerApp/work_tracker_venv/lib/python3.13/site-packages/httpcore/_sync/connection_pool.py", line 236, in handle_request
    response = connection.handle_request(
        pool_request.request
    )
  File "/Users/adeoluwa/Documents/WorkTrackerApp/work_tracker_venv/lib/python3.13/site-packages/httpcore/_sync/connection.py", line 101, in handle_request
    raise exc
  File "/Users/adeoluwa/Documents/WorkTrackerApp/work_tracker_venv/lib/python3.13/site-packages/httpcore/_sync/connection.py", line 78, in handle_request
    stream = self._connect(request)
  File "/Users/adeoluwa/Documents/WorkTrackerApp/work_tracker_venv/lib/python3.13/site-packages/httpcore/_sync/connection.py", line 156, in _connect
    stream = stream.start_tls(**kwargs)
  File "/Users/adeoluwa/Documents/WorkTrackerApp/work_tracker_venv/lib/python3.13/site-packages/httpcore/_backends/sync.py", line 154, in start_tls
    with map_exceptions(exc_map):
         ~~~~~~~~~~~~~~^^^^^^^^^
  File "/Library/Frameworks/Python.framework/Versions/3.13/lib/python3.13/contextlib.py", line 162, in __exit__
    self.gen.throw(value)
    ~~~~~~~~~~~~~~^^^^^^^
  File "/Users/adeoluwa/Documents/WorkTrackerApp/work_tracker_venv/lib/python3.13/site-packages/httpcore/_exceptions.py", line 14, in map_exceptions
    raise to_exc(exc) from exc
httpcore.ConnectError: [Errno 54] Connection reset by peer

The above exception was the direct cause of the following exception:

Traceback (most recent call last):
  File "/Users/adeoluwa/Documents/WorkTrackerApp/main.py", line 301, in _send_supabase_data
    response = self.supabase_client.table(table_name).upsert(data).execute()
  File "/Users/adeoluwa/Documents/WorkTrackerApp/work_tracker_venv/lib/python3.13/site-packages/postgrest/_sync/request_builder.py", line 57, in execute
    r = self.session.request(
        self.http_method,
    ...<3 lines>...
        headers=self.headers,
    )
  File "/Users/adeoluwa/Documents/WorkTrackerApp/work_tracker_venv/lib/python3.13/site-packages/httpx/_client.py", line 825, in request
    return self.send(request, auth=auth, follow_redirects=follow_redirects)
           ~~~~~~~~~^^^^^^^^^^^^^^^^^^^^^^^^^^^^^^^^^^^^^^^^^^^^^^^^^^^^^^^
  File "/Users/adeoluwa/Documents/WorkTrackerApp/work_tracker_venv/lib/python3.13/site-packages/httpx/_client.py", line 914, in send
    response = self._send_handling_auth(
        request,
    ...<2 lines>...
        history=[],
    )
  File "/Users/adeoluwa/Documents/WorkTrackerApp/work_tracker_venv/lib/python3.13/site-packages/httpx/_client.py", line 942, in _send_handling_auth
    response = self._send_handling_redirects(
        request,
        follow_redirects=follow_redirects,
        history=history,
    )
  File "/Users/adeoluwa/Documents/WorkTrackerApp/work_tracker_venv/lib/python3.13/site-packages/httpx/_client.py", line 979, in _send_handling_redirects
    response = self._send_single_request(request)
  File "/Users/adeoluwa/Documents/WorkTrackerApp/work_tracker_venv/lib/python3.13/site-packages/httpx/_client.py", line 1014, in _send_single_request
    response = transport.handle_request(request)
  File "/Users/adeoluwa/Documents/WorkTrackerApp/work_tracker_venv/lib/python3.13/site-packages/httpx/_transports/default.py", line 249, in handle_request
    with map_httpcore_exceptions():
         ~~~~~~~~~~~~~~~~~~~~~~~^^
  File "/Library/Frameworks/Python.framework/Versions/3.13/lib/python3.13/contextlib.py", line 162, in __exit__
    self.gen.throw(value)
    ~~~~~~~~~~~~~~^^^^^^^
  File "/Users/adeoluwa/Documents/WorkTrackerApp/work_tracker_venv/lib/python3.13/site-packages/httpx/_transports/default.py", line 118, in map_httpcore_exceptions
    raise mapped_exc(message) from exc
httpx.ConnectError: [Errno 54] Connection reset by peer
2025-07-12 16:39:20,001 - ERROR - Failed to send heartbeat to cloud.
2025-07-12 18:05:34,557 - ERROR - Error sending data to Supabase table 'online_status': [Errno 8] nodename nor servname provided, or not known
Traceback (most recent call last):
  File "/Users/adeoluwa/Documents/WorkTrackerApp/work_tracker_venv/lib/python3.13/site-packages/httpx/_transports/default.py", line 101, in map_httpcore_exceptions
    yield
  File "/Users/adeoluwa/Documents/WorkTrackerApp/work_tracker_venv/lib/python3.13/site-packages/httpx/_transports/default.py", line 250, in handle_request
    resp = self._pool.handle_request(req)
  File "/Users/adeoluwa/Documents/WorkTrackerApp/work_tracker_venv/lib/python3.13/site-packages/httpcore/_sync/connection_pool.py", line 256, in handle_request
    raise exc from None
  File "/Users/adeoluwa/Documents/WorkTrackerApp/work_tracker_venv/lib/python3.13/site-packages/httpcore/_sync/connection_pool.py", line 236, in handle_request
    response = connection.handle_request(
        pool_request.request
    )
  File "/Users/adeoluwa/Documents/WorkTrackerApp/work_tracker_venv/lib/python3.13/site-packages/httpcore/_sync/connection.py", line 101, in handle_request
    raise exc
  File "/Users/adeoluwa/Documents/WorkTrackerApp/work_tracker_venv/lib/python3.13/site-packages/httpcore/_sync/connection.py", line 78, in handle_request
    stream = self._connect(request)
  File "/Users/adeoluwa/Documents/WorkTrackerApp/work_tracker_venv/lib/python3.13/site-packages/httpcore/_sync/connection.py", line 124, in _connect
    stream = self._network_backend.connect_tcp(**kwargs)
  File "/Users/adeoluwa/Documents/WorkTrackerApp/work_tracker_venv/lib/python3.13/site-packages/httpcore/_backends/sync.py", line 207, in connect_tcp
    with map_exceptions(exc_map):
         ~~~~~~~~~~~~~~^^^^^^^^^
  File "/Library/Frameworks/Python.framework/Versions/3.13/lib/python3.13/contextlib.py", line 162, in __exit__
    self.gen.throw(value)
    ~~~~~~~~~~~~~~^^^^^^^
  File "/Users/adeoluwa/Documents/WorkTrackerApp/work_tracker_venv/lib/python3.13/site-packages/httpcore/_exceptions.py", line 14, in map_exceptions
    raise to_exc(exc) from exc
httpcore.ConnectError: [Errno 8] nodename nor servname provided, or not known

The above exception was the direct cause of the following exception:

Traceback (most recent call last):
  File "/Users/adeoluwa/Documents/WorkTrackerApp/main.py", line 301, in _send_supabase_data
    response = self.supabase_client.table(table_name).upsert(data).execute()
  File "/Users/adeoluwa/Documents/WorkTrackerApp/work_tracker_venv/lib/python3.13/site-packages/postgrest/_sync/request_builder.py", line 57, in execute
    r = self.session.request(
        self.http_method,
    ...<3 lines>...
        headers=self.headers,
    )
  File "/Users/adeoluwa/Documents/WorkTrackerApp/work_tracker_venv/lib/python3.13/site-packages/httpx/_client.py", line 825, in request
    return self.send(request, auth=auth, follow_redirects=follow_redirects)
           ~~~~~~~~~^^^^^^^^^^^^^^^^^^^^^^^^^^^^^^^^^^^^^^^^^^^^^^^^^^^^^^^
  File "/Users/adeoluwa/Documents/WorkTrackerApp/work_tracker_venv/lib/python3.13/site-packages/httpx/_client.py", line 914, in send
    response = self._send_handling_auth(
        request,
    ...<2 lines>...
        history=[],
    )
  File "/Users/adeoluwa/Documents/WorkTrackerApp/work_tracker_venv/lib/python3.13/site-packages/httpx/_client.py", line 942, in _send_handling_auth
    response = self._send_handling_redirects(
        request,
        follow_redirects=follow_redirects,
        history=history,
    )
  File "/Users/adeoluwa/Documents/WorkTrackerApp/work_tracker_venv/lib/python3.13/site-packages/httpx/_client.py", line 979, in _send_handling_redirects
    response = self._send_single_request(request)
  File "/Users/adeoluwa/Documents/WorkTrackerApp/work_tracker_venv/lib/python3.13/site-packages/httpx/_client.py", line 1014, in _send_single_request
    response = transport.handle_request(request)
  File "/Users/adeoluwa/Documents/WorkTrackerApp/work_tracker_venv/lib/python3.13/site-packages/httpx/_transports/default.py", line 249, in handle_request
    with map_httpcore_exceptions():
         ~~~~~~~~~~~~~~~~~~~~~~~^^
  File "/Library/Frameworks/Python.framework/Versions/3.13/lib/python3.13/contextlib.py", line 162, in __exit__
    self.gen.throw(value)
    ~~~~~~~~~~~~~~^^^^^^^
  File "/Users/adeoluwa/Documents/WorkTrackerApp/work_tracker_venv/lib/python3.13/site-packages/httpx/_transports/default.py", line 118, in map_httpcore_exceptions
    raise mapped_exc(message) from exc
httpx.ConnectError: [Errno 8] nodename nor servname provided, or not known
2025-07-12 18:05:34,637 - ERROR - Failed to send heartbeat to cloud.
2025-07-12 18:48:46,814 - ERROR - Error sending data to Supabase table 'online_status': [Errno 60] Operation timed out
Traceback (most recent call last):
  File "/Users/adeoluwa/Documents/WorkTrackerApp/work_tracker_venv/lib/python3.13/site-packages/httpx/_transports/default.py", line 101, in map_httpcore_exceptions
    yield
  File "/Users/adeoluwa/Documents/WorkTrackerApp/work_tracker_venv/lib/python3.13/site-packages/httpx/_transports/default.py", line 250, in handle_request
    resp = self._pool.handle_request(req)
  File "/Users/adeoluwa/Documents/WorkTrackerApp/work_tracker_venv/lib/python3.13/site-packages/httpcore/_sync/connection_pool.py", line 256, in handle_request
    raise exc from None
  File "/Users/adeoluwa/Documents/WorkTrackerApp/work_tracker_venv/lib/python3.13/site-packages/httpcore/_sync/connection_pool.py", line 236, in handle_request
    response = connection.handle_request(
        pool_request.request
    )
  File "/Users/adeoluwa/Documents/WorkTrackerApp/work_tracker_venv/lib/python3.13/site-packages/httpcore/_sync/connection.py", line 101, in handle_request
    raise exc
  File "/Users/adeoluwa/Documents/WorkTrackerApp/work_tracker_venv/lib/python3.13/site-packages/httpcore/_sync/connection.py", line 78, in handle_request
    stream = self._connect(request)
  File "/Users/adeoluwa/Documents/WorkTrackerApp/work_tracker_venv/lib/python3.13/site-packages/httpcore/_sync/connection.py", line 124, in _connect
    stream = self._network_backend.connect_tcp(**kwargs)
  File "/Users/adeoluwa/Documents/WorkTrackerApp/work_tracker_venv/lib/python3.13/site-packages/httpcore/_backends/sync.py", line 207, in connect_tcp
    with map_exceptions(exc_map):
         ~~~~~~~~~~~~~~^^^^^^^^^
  File "/Library/Frameworks/Python.framework/Versions/3.13/lib/python3.13/contextlib.py", line 162, in __exit__
    self.gen.throw(value)
    ~~~~~~~~~~~~~~^^^^^^^
  File "/Users/adeoluwa/Documents/WorkTrackerApp/work_tracker_venv/lib/python3.13/site-packages/httpcore/_exceptions.py", line 14, in map_exceptions
    raise to_exc(exc) from exc
httpcore.ConnectTimeout: [Errno 60] Operation timed out

The above exception was the direct cause of the following exception:

Traceback (most recent call last):
  File "/Users/adeoluwa/Documents/WorkTrackerApp/main.py", line 301, in _send_supabase_data
    response = self.supabase_client.table(table_name).upsert(data).execute()
  File "/Users/adeoluwa/Documents/WorkTrackerApp/work_tracker_venv/lib/python3.13/site-packages/postgrest/_sync/request_builder.py", line 57, in execute
    r = self.session.request(
        self.http_method,
    ...<3 lines>...
        headers=self.headers,
    )
  File "/Users/adeoluwa/Documents/WorkTrackerApp/work_tracker_venv/lib/python3.13/site-packages/httpx/_client.py", line 825, in request
    return self.send(request, auth=auth, follow_redirects=follow_redirects)
           ~~~~~~~~~^^^^^^^^^^^^^^^^^^^^^^^^^^^^^^^^^^^^^^^^^^^^^^^^^^^^^^^
  File "/Users/adeoluwa/Documents/WorkTrackerApp/work_tracker_venv/lib/python3.13/site-packages/httpx/_client.py", line 914, in send
    response = self._send_handling_auth(
        request,
    ...<2 lines>...
        history=[],
    )
  File "/Users/adeoluwa/Documents/WorkTrackerApp/work_tracker_venv/lib/python3.13/site-packages/httpx/_client.py", line 942, in _send_handling_auth
    response = self._send_handling_redirects(
        request,
        follow_redirects=follow_redirects,
        history=history,
    )
  File "/Users/adeoluwa/Documents/WorkTrackerApp/work_tracker_venv/lib/python3.13/site-packages/httpx/_client.py", line 979, in _send_handling_redirects
    response = self._send_single_request(request)
  File "/Users/adeoluwa/Documents/WorkTrackerApp/work_tracker_venv/lib/python3.13/site-packages/httpx/_client.py", line 1014, in _send_single_request
    response = transport.handle_request(request)
  File "/Users/adeoluwa/Documents/WorkTrackerApp/work_tracker_venv/lib/python3.13/site-packages/httpx/_transports/default.py", line 249, in handle_request
    with map_httpcore_exceptions():
         ~~~~~~~~~~~~~~~~~~~~~~~^^
  File "/Library/Frameworks/Python.framework/Versions/3.13/lib/python3.13/contextlib.py", line 162, in __exit__
    self.gen.throw(value)
    ~~~~~~~~~~~~~~^^^^^^^
  File "/Users/adeoluwa/Documents/WorkTrackerApp/work_tracker_venv/lib/python3.13/site-packages/httpx/_transports/default.py", line 118, in map_httpcore_exceptions
    raise mapped_exc(message) from exc
httpx.ConnectTimeout: [Errno 60] Operation timed out
2025-07-12 18:48:46,822 - ERROR - Failed to send heartbeat to cloud.
2025-07-12 20:09:58,916 - ERROR - Error sending data to Supabase table 'online_status': [Errno 54] Connection reset by peer
Traceback (most recent call last):
  File "/Users/adeoluwa/Documents/WorkTrackerApp/work_tracker_venv/lib/python3.13/site-packages/httpx/_transports/default.py", line 101, in map_httpcore_exceptions
    yield
  File "/Users/adeoluwa/Documents/WorkTrackerApp/work_tracker_venv/lib/python3.13/site-packages/httpx/_transports/default.py", line 250, in handle_request
    resp = self._pool.handle_request(req)
  File "/Users/adeoluwa/Documents/WorkTrackerApp/work_tracker_venv/lib/python3.13/site-packages/httpcore/_sync/connection_pool.py", line 256, in handle_request
    raise exc from None
  File "/Users/adeoluwa/Documents/WorkTrackerApp/work_tracker_venv/lib/python3.13/site-packages/httpcore/_sync/connection_pool.py", line 236, in handle_request
    response = connection.handle_request(
        pool_request.request
    )
  File "/Users/adeoluwa/Documents/WorkTrackerApp/work_tracker_venv/lib/python3.13/site-packages/httpcore/_sync/connection.py", line 101, in handle_request
    raise exc
  File "/Users/adeoluwa/Documents/WorkTrackerApp/work_tracker_venv/lib/python3.13/site-packages/httpcore/_sync/connection.py", line 78, in handle_request
    stream = self._connect(request)
  File "/Users/adeoluwa/Documents/WorkTrackerApp/work_tracker_venv/lib/python3.13/site-packages/httpcore/_sync/connection.py", line 156, in _connect
    stream = stream.start_tls(**kwargs)
  File "/Users/adeoluwa/Documents/WorkTrackerApp/work_tracker_venv/lib/python3.13/site-packages/httpcore/_backends/sync.py", line 154, in start_tls
    with map_exceptions(exc_map):
         ~~~~~~~~~~~~~~^^^^^^^^^
  File "/Library/Frameworks/Python.framework/Versions/3.13/lib/python3.13/contextlib.py", line 162, in __exit__
    self.gen.throw(value)
    ~~~~~~~~~~~~~~^^^^^^^
  File "/Users/adeoluwa/Documents/WorkTrackerApp/work_tracker_venv/lib/python3.13/site-packages/httpcore/_exceptions.py", line 14, in map_exceptions
    raise to_exc(exc) from exc
httpcore.ConnectError: [Errno 54] Connection reset by peer

The above exception was the direct cause of the following exception:

Traceback (most recent call last):
  File "/Users/adeoluwa/Documents/WorkTrackerApp/main.py", line 301, in _send_supabase_data
    response = self.supabase_client.table(table_name).upsert(data).execute()
  File "/Users/adeoluwa/Documents/WorkTrackerApp/work_tracker_venv/lib/python3.13/site-packages/postgrest/_sync/request_builder.py", line 57, in execute
    r = self.session.request(
        self.http_method,
    ...<3 lines>...
        headers=self.headers,
    )
  File "/Users/adeoluwa/Documents/WorkTrackerApp/work_tracker_venv/lib/python3.13/site-packages/httpx/_client.py", line 825, in request
    return self.send(request, auth=auth, follow_redirects=follow_redirects)
           ~~~~~~~~~^^^^^^^^^^^^^^^^^^^^^^^^^^^^^^^^^^^^^^^^^^^^^^^^^^^^^^^
  File "/Users/adeoluwa/Documents/WorkTrackerApp/work_tracker_venv/lib/python3.13/site-packages/httpx/_client.py", line 914, in send
    response = self._send_handling_auth(
        request,
    ...<2 lines>...
        history=[],
    )
  File "/Users/adeoluwa/Documents/WorkTrackerApp/work_tracker_venv/lib/python3.13/site-packages/httpx/_client.py", line 942, in _send_handling_auth
    response = self._send_handling_redirects(
        request,
        follow_redirects=follow_redirects,
        history=history,
    )
  File "/Users/adeoluwa/Documents/WorkTrackerApp/work_tracker_venv/lib/python3.13/site-packages/httpx/_client.py", line 979, in _send_handling_redirects
    response = self._send_single_request(request)
  File "/Users/adeoluwa/Documents/WorkTrackerApp/work_tracker_venv/lib/python3.13/site-packages/httpx/_client.py", line 1014, in _send_single_request
    response = transport.handle_request(request)
  File "/Users/adeoluwa/Documents/WorkTrackerApp/work_tracker_venv/lib/python3.13/site-packages/httpx/_transports/default.py", line 249, in handle_request
    with map_httpcore_exceptions():
         ~~~~~~~~~~~~~~~~~~~~~~~^^
  File "/Library/Frameworks/Python.framework/Versions/3.13/lib/python3.13/contextlib.py", line 162, in __exit__
    self.gen.throw(value)
    ~~~~~~~~~~~~~~^^^^^^^
  File "/Users/adeoluwa/Documents/WorkTrackerApp/work_tracker_venv/lib/python3.13/site-packages/httpx/_transports/default.py", line 118, in map_httpcore_exceptions
    raise mapped_exc(message) from exc
httpx.ConnectError: [Errno 54] Connection reset by peer
2025-07-12 20:09:58,937 - ERROR - Failed to send heartbeat to cloud.
