2025-07-13 16:44:13,161 - ERROR - Error saving authentication token: [Errno 2] No such file or directory: '/Users/adeoluwa/Library/Application Support/WorkTracker/token.json'
2025-07-13 16:45:08,710 - ERROR - Error saving authentication token: [Errno 2] No such file or directory: '/Users/adeoluwa/Library/Application Support/WorkTracker/token.json'
2025-07-13 17:06:47,503 - ERROR - Error sending data to Supabase table 'online_status': [Errno 54] Connection reset by peer
Traceback (most recent call last):
  File "/Users/adeoluwa/Documents/WorkTrackerApp/work_tracker_venv/lib/python3.13/site-packages/httpx/_transports/default.py", line 101, in map_httpcore_exceptions
    yield
  File "/Users/adeoluwa/Documents/WorkTrackerApp/work_tracker_venv/lib/python3.13/site-packages/httpx/_transports/default.py", line 250, in handle_request
    resp = self._pool.handle_request(req)
  File "/Users/adeoluwa/Documents/WorkTrackerApp/work_tracker_venv/lib/python3.13/site-packages/httpcore/_sync/connection_pool.py", line 256, in handle_request
    raise exc from None
  File "/Users/adeoluwa/Documents/WorkTrackerApp/work_tracker_venv/lib/python3.13/site-packages/httpcore/_sync/connection_pool.py", line 236, in handle_request
    response = connection.handle_request(
        pool_request.request
    )
  File "/Users/adeoluwa/Documents/WorkTrackerApp/work_tracker_venv/lib/python3.13/site-packages/httpcore/_sync/connection.py", line 101, in handle_request
    raise exc
  File "/Users/adeoluwa/Documents/WorkTrackerApp/work_tracker_venv/lib/python3.13/site-packages/httpcore/_sync/connection.py", line 78, in handle_request
    stream = self._connect(request)
  File "/Users/adeoluwa/Documents/WorkTrackerApp/work_tracker_venv/lib/python3.13/site-packages/httpcore/_sync/connection.py", line 156, in _connect
    stream = stream.start_tls(**kwargs)
  File "/Users/adeoluwa/Documents/WorkTrackerApp/work_tracker_venv/lib/python3.13/site-packages/httpcore/_backends/sync.py", line 154, in start_tls
    with map_exceptions(exc_map):
         ~~~~~~~~~~~~~~^^^^^^^^^
  File "/Library/Frameworks/Python.framework/Versions/3.13/lib/python3.13/contextlib.py", line 162, in __exit__
    self.gen.throw(value)
    ~~~~~~~~~~~~~~^^^^^^^
  File "/Users/adeoluwa/Documents/WorkTrackerApp/work_tracker_venv/lib/python3.13/site-packages/httpcore/_exceptions.py", line 14, in map_exceptions
    raise to_exc(exc) from exc
httpcore.ConnectError: [Errno 54] Connection reset by peer

The above exception was the direct cause of the following exception:

Traceback (most recent call last):
  File "/Users/adeoluwa/Documents/WorkTrackerApp/main.py", line 315, in _send_supabase_data
    response = self.supabase_client.table(table_name).upsert(data).execute()
  File "/Users/adeoluwa/Documents/WorkTrackerApp/work_tracker_venv/lib/python3.13/site-packages/postgrest/_sync/request_builder.py", line 57, in execute
    r = self.session.request(
        self.http_method,
    ...<3 lines>...
        headers=self.headers,
    )
  File "/Users/adeoluwa/Documents/WorkTrackerApp/work_tracker_venv/lib/python3.13/site-packages/httpx/_client.py", line 825, in request
    return self.send(request, auth=auth, follow_redirects=follow_redirects)
           ~~~~~~~~~^^^^^^^^^^^^^^^^^^^^^^^^^^^^^^^^^^^^^^^^^^^^^^^^^^^^^^^
  File "/Users/adeoluwa/Documents/WorkTrackerApp/work_tracker_venv/lib/python3.13/site-packages/httpx/_client.py", line 914, in send
    response = self._send_handling_auth(
        request,
    ...<2 lines>...
        history=[],
    )
  File "/Users/adeoluwa/Documents/WorkTrackerApp/work_tracker_venv/lib/python3.13/site-packages/httpx/_client.py", line 942, in _send_handling_auth
    response = self._send_handling_redirects(
        request,
        follow_redirects=follow_redirects,
        history=history,
    )
  File "/Users/adeoluwa/Documents/WorkTrackerApp/work_tracker_venv/lib/python3.13/site-packages/httpx/_client.py", line 979, in _send_handling_redirects
    response = self._send_single_request(request)
  File "/Users/adeoluwa/Documents/WorkTrackerApp/work_tracker_venv/lib/python3.13/site-packages/httpx/_client.py", line 1014, in _send_single_request
    response = transport.handle_request(request)
  File "/Users/adeoluwa/Documents/WorkTrackerApp/work_tracker_venv/lib/python3.13/site-packages/httpx/_transports/default.py", line 249, in handle_request
    with map_httpcore_exceptions():
         ~~~~~~~~~~~~~~~~~~~~~~~^^
  File "/Library/Frameworks/Python.framework/Versions/3.13/lib/python3.13/contextlib.py", line 162, in __exit__
    self.gen.throw(value)
    ~~~~~~~~~~~~~~^^^^^^^
  File "/Users/adeoluwa/Documents/WorkTrackerApp/work_tracker_venv/lib/python3.13/site-packages/httpx/_transports/default.py", line 118, in map_httpcore_exceptions
    raise mapped_exc(message) from exc
httpx.ConnectError: [Errno 54] Connection reset by peer
2025-07-13 17:06:47,515 - ERROR - Failed to send heartbeat to cloud.
2025-07-13 17:37:16,672 - ERROR - Error sending data to Supabase table 'online_status': [Errno 60] Operation timed out
Traceback (most recent call last):
  File "/Users/adeoluwa/Documents/WorkTrackerApp/work_tracker_venv/lib/python3.13/site-packages/httpx/_transports/default.py", line 101, in map_httpcore_exceptions
    yield
  File "/Users/adeoluwa/Documents/WorkTrackerApp/work_tracker_venv/lib/python3.13/site-packages/httpx/_transports/default.py", line 250, in handle_request
    resp = self._pool.handle_request(req)
  File "/Users/adeoluwa/Documents/WorkTrackerApp/work_tracker_venv/lib/python3.13/site-packages/httpcore/_sync/connection_pool.py", line 256, in handle_request
    raise exc from None
  File "/Users/adeoluwa/Documents/WorkTrackerApp/work_tracker_venv/lib/python3.13/site-packages/httpcore/_sync/connection_pool.py", line 236, in handle_request
    response = connection.handle_request(
        pool_request.request
    )
  File "/Users/adeoluwa/Documents/WorkTrackerApp/work_tracker_venv/lib/python3.13/site-packages/httpcore/_sync/connection.py", line 101, in handle_request
    raise exc
  File "/Users/adeoluwa/Documents/WorkTrackerApp/work_tracker_venv/lib/python3.13/site-packages/httpcore/_sync/connection.py", line 78, in handle_request
    stream = self._connect(request)
  File "/Users/adeoluwa/Documents/WorkTrackerApp/work_tracker_venv/lib/python3.13/site-packages/httpcore/_sync/connection.py", line 124, in _connect
    stream = self._network_backend.connect_tcp(**kwargs)
  File "/Users/adeoluwa/Documents/WorkTrackerApp/work_tracker_venv/lib/python3.13/site-packages/httpcore/_backends/sync.py", line 207, in connect_tcp
    with map_exceptions(exc_map):
         ~~~~~~~~~~~~~~^^^^^^^^^
  File "/Library/Frameworks/Python.framework/Versions/3.13/lib/python3.13/contextlib.py", line 162, in __exit__
    self.gen.throw(value)
    ~~~~~~~~~~~~~~^^^^^^^
  File "/Users/adeoluwa/Documents/WorkTrackerApp/work_tracker_venv/lib/python3.13/site-packages/httpcore/_exceptions.py", line 14, in map_exceptions
    raise to_exc(exc) from exc
httpcore.ConnectTimeout: [Errno 60] Operation timed out

The above exception was the direct cause of the following exception:

Traceback (most recent call last):
  File "/Users/adeoluwa/Documents/WorkTrackerApp/main.py", line 315, in _send_supabase_data
    response = self.supabase_client.table(table_name).upsert(data).execute()
  File "/Users/adeoluwa/Documents/WorkTrackerApp/work_tracker_venv/lib/python3.13/site-packages/postgrest/_sync/request_builder.py", line 57, in execute
    r = self.session.request(
        self.http_method,
    ...<3 lines>...
        headers=self.headers,
    )
  File "/Users/adeoluwa/Documents/WorkTrackerApp/work_tracker_venv/lib/python3.13/site-packages/httpx/_client.py", line 825, in request
    return self.send(request, auth=auth, follow_redirects=follow_redirects)
           ~~~~~~~~~^^^^^^^^^^^^^^^^^^^^^^^^^^^^^^^^^^^^^^^^^^^^^^^^^^^^^^^
  File "/Users/adeoluwa/Documents/WorkTrackerApp/work_tracker_venv/lib/python3.13/site-packages/httpx/_client.py", line 914, in send
    response = self._send_handling_auth(
        request,
    ...<2 lines>...
        history=[],
    )
  File "/Users/adeoluwa/Documents/WorkTrackerApp/work_tracker_venv/lib/python3.13/site-packages/httpx/_client.py", line 942, in _send_handling_auth
    response = self._send_handling_redirects(
        request,
        follow_redirects=follow_redirects,
        history=history,
    )
  File "/Users/adeoluwa/Documents/WorkTrackerApp/work_tracker_venv/lib/python3.13/site-packages/httpx/_client.py", line 979, in _send_handling_redirects
    response = self._send_single_request(request)
  File "/Users/adeoluwa/Documents/WorkTrackerApp/work_tracker_venv/lib/python3.13/site-packages/httpx/_client.py", line 1014, in _send_single_request
    response = transport.handle_request(request)
  File "/Users/adeoluwa/Documents/WorkTrackerApp/work_tracker_venv/lib/python3.13/site-packages/httpx/_transports/default.py", line 249, in handle_request
    with map_httpcore_exceptions():
         ~~~~~~~~~~~~~~~~~~~~~~~^^
  File "/Library/Frameworks/Python.framework/Versions/3.13/lib/python3.13/contextlib.py", line 162, in __exit__
    self.gen.throw(value)
    ~~~~~~~~~~~~~~^^^^^^^
  File "/Users/adeoluwa/Documents/WorkTrackerApp/work_tracker_venv/lib/python3.13/site-packages/httpx/_transports/default.py", line 118, in map_httpcore_exceptions
    raise mapped_exc(message) from exc
httpx.ConnectTimeout: [Errno 60] Operation timed out
2025-07-13 17:37:16,680 - ERROR - Failed to send heartbeat to cloud.
2025-07-13 19:00:38,965 - ERROR - Unknown database operation: get_deleted_task_ids
2025-07-13 19:00:39,642 - ERROR - Unknown database operation: update_task_with_google_id
2025-07-13 19:00:39,932 - ERROR - Unknown database operation: update_task_with_google_id
2025-07-13 19:00:39,932 - ERROR - Database operation 'insert_task' failed: Database.insert_task() takes 3 positional arguments but 5 were given
2025-07-13 19:00:39,932 - ERROR - Database operation 'insert_task' failed: Database.insert_task() takes 3 positional arguments but 5 were given
2025-07-13 19:00:39,932 - ERROR - Database operation 'insert_task' failed: Database.insert_task() takes 3 positional arguments but 5 were given
2025-07-13 19:00:39,932 - ERROR - Database operation 'insert_task' failed: Database.insert_task() takes 3 positional arguments but 5 were given
2025-07-13 19:00:39,932 - ERROR - Database operation 'insert_task' failed: Database.insert_task() takes 3 positional arguments but 5 were given
2025-07-13 19:00:39,932 - ERROR - Database operation 'insert_task' failed: Database.insert_task() takes 3 positional arguments but 5 were given
2025-07-13 19:00:39,932 - ERROR - Database operation 'insert_task' failed: Database.insert_task() takes 3 positional arguments but 5 were given
2025-07-13 19:00:39,932 - ERROR - Database operation 'insert_task' failed: Database.insert_task() takes 3 positional arguments but 5 were given
2025-07-13 19:00:39,932 - ERROR - Database operation 'insert_task' failed: Database.insert_task() takes 3 positional arguments but 5 were given
2025-07-13 19:00:39,932 - ERROR - Database operation 'insert_task' failed: Database.insert_task() takes 3 positional arguments but 5 were given
2025-07-13 19:23:54,929 - ERROR - Database query failed: SELECT id, title, status, starred, google_task_id, last_modified FROM tasks WHERE deleted = 0 with params (). Error: no such column: deleted
2025-07-13 19:44:18,376 - ERROR - Failed to create new task on Google: <HttpError 503 when requesting https://tasks.googleapis.com/tasks/v1/lists/MTQwMDg5NzA2MTg5NDM5MDkzMDQ6MDow/tasks?alt=json returned "The service is currently unavailable.". Details: "[{'message': 'The service is currently unavailable.', 'domain': 'global', 'reason': 'backendError'}]">
